<?xml version="1.0"?>
<robot xmlns:xacro="http://www.ros.org/wiki/xacro">

    <xacro:include filename="robot_colors.xacro"/>
    <xacro:include filename="inertial_macros.xacro" />

    <!-- BASE LINK -->

    <link name="base_link">

    </link>


    <!-- CHASSIS LINK -->

    <joint name="chassis_joint" type="fixed">
        <parent link="base_link"/>
        <child link="chassis"/>
        <origin xyz="0 0 0.05"/>
    </joint>

    <link name="chassis">
        <visual>
            <origin xyz="0 0 0.075" rpy="0 0 0"/>
            <geometry>
                <box size="0.3048 0.2032 0.15"/>
            </geometry>
            <material name="white"/>
        </visual>
        <collision>
            <origin xyz="0 0 0.075" rpy="0 0 0"/>
            <geometry>
                <box size="0.3048 0.2032 0.15"/>
            </geometry>
        </collision>
        <xacro:inertial_box mass="0.5" x="0.3048" y="0.2032" z="0.15">
            <origin xyz="0 0 0.075" rpy="0 0 0"/>
        </xacro:inertial_box>
    </link>

    <!-- LEFT FRONT WHEEL -->

    <joint name="left_front_wheel_joint" type="continuous">
        <parent link="base_link"/>
        <child link="left_front_wheel"/>
        <origin xyz="0.127 0.1241 0.075" rpy="-${pi/2} 0 0"/>
        <axis xyz="0 0 1"/>
    </joint>

    <link name="left_front_wheel">
        <visual>
            <geometry>
                <cylinder length="0.045" radius="0.048" />
            </geometry>
            <material name="blue"/>
        </visual>
        <collision>
            <geometry>
                <cylinder length="0.045" radius="0.048" />
            </geometry>
        </collision>
        <xacro:inertial_cylinder mass="0.1" length="0.045" radius="0.048">
            <origin xyz="0.127 0.1241 0.075" rpy="-${pi/2} 0 0"/>
        </xacro:inertial_cylinder>
    </link>

    <!-- LEFT BACK WHEEL -->

    <joint name="left_back_wheel_joint" type="continuous">
        <parent link="base_link"/>
        <child link="left_back_wheel"/>
        <origin xyz="-0.127 0.1241 0.075" rpy="-${pi/2} 0 0"/>
        <axis xyz="0 0 1"/>
    </joint>

    <link name="left_back_wheel">
        <visual>
            <geometry>
                 <cylinder length="0.045" radius="0.048" />
            </geometry>
            <material name="blue"/>
        </visual>
        <collision>
            <geometry>
                 <cylinder length="0.045" radius="0.048" />
            </geometry>
        </collision>
        <xacro:inertial_cylinder mass="0.1" length="0.045" radius="0.048">
            <origin xyz="-0.127 0.1241 0.075" rpy="-${pi/2} 0 0"/>
        </xacro:inertial_cylinder>
    </link>

    <!-- RIGHT FRONT WHEEL -->

    <joint name="right_front_wheel_joint" type="continuous">
        <parent link="base_link"/>
        <child link="right_front_wheel"/>
        <origin xyz="0.127 -0.1241 0.075" rpy="${pi/2} 0 0"/>
        <axis xyz="0 0 -1"/>
    </joint>

    <link name="right_front_wheel">
        <visual>
            <geometry>
                <cylinder length="0.045" radius="0.048" />
            </geometry>
            <material name="blue"/>
        </visual>
        <collision>
            <geometry>
                <cylinder length="0.045" radius="0.048" />
            </geometry>
        </collision>
        <xacro:inertial_cylinder mass="0.1" length="0.045" radius="0.048">
            <origin xyz="0.127 -0.1241 0.075" rpy="${pi/2} 0 0"/>
        </xacro:inertial_cylinder>
    </link>

    <!-- RIGHT BACK WHEEL -->

    <joint name="right_back_wheel_joint" type="continuous">
        <parent link="base_link"/>
        <child link="right_back_wheel"/>
        <origin xyz="-0.127 -0.1241 0.075" rpy="${pi/2} 0 0"/>
        <axis xyz="0 0 -1"/>
    </joint>

    <link name="right_back_wheel">
        <visual>
            <geometry>
                <cylinder length="0.045" radius="0.048" />
            </geometry>
            <material name="blue"/>
        </visual>
        <collision>
            <geometry>
                <cylinder length="0.045" radius="0.048" />
            </geometry>
        </collision>
        <xacro:inertial_cylinder mass="0.1" length="0.045" radius="0.048">
            <origin xyz="-0.127 -0.1241 0.075" rpy="${pi/2} 0 0"/>
        </xacro:inertial_cylinder>
    </link>

</robot>